Workbook

Sheet Census
C3: INSTRUCTIONS 1. Every worksite employee and all enrolled dependent(s) should be included on the census (legal names only). 2. Please group all family members together. Each employee and each dependent should be given their own row as displayed in the sample below (one row for an employee, a row below that for their spouse, a row below that for their child, etc.). To designate each member enrollee type please select from the dropdown menu in the "Expected Enrollee Type" column. 3. Current individuals enrolled in COBRA must be included on the census in their own row. To identify COBRA enrollees please select "COBRA Enrollee" as their "Expected Enrollee Type". 4. Please identify all part time employees (employees that work less than 30 hours per week) on the census. This can be done by selecting "Not Eligible for Benefits" as their "Expected Enrollee Type".
C12: REQUIRED FOR ALL COMPANIES
C15: What is your company name? | E15: Nucor Employee's Credit Union
C16: What is the full address of your company headquarters? | E16: 1202 N Cashua Dr. Florence, SC 29501
C17: What year was your company founded? | E17: 1962
C18: Do you currently offer health insurance? | E18: Yes
C19: When will you need your coverage to begin? | E19: 46722
C21: First Name | D21: Last Name | E21: Sex | F21: Date of Birth | G21: Home Zip Code | H21: Job Title | I21: Salary | J21: Employee Types - Full or Part Time | K21: Workers Comp Code | L21: Enrollee Type
B23: 1 | C23: Matthew | D23: Chappell | E23: M | F23: 32110 | G23: 29505 | H23: Mgr | I23: 123000 | J23: F | L23: Employee
B24: 2 | C24: Amy | D24: Chappell | E24: F | F24: 32199 | G24: 29505 | L24: Spouse of Employee
B25: 3 | C25: Silas | D25: Chappell | E25: M | F25: 44729 | G25: 29505 | L25: Child of Employee
B26: 4 | C26: Isaac | D26: Chappell | E26: M | F26: 45415 | G26: 29505 | L26: Child of Employee
B27: 5 | C27: Debbie | D27: McGee | E27: F | F27: 26289 | G27: 29010 | H27: Asst. Mgr | I27: 84590 | J27: F | L27: Employee
B28: 6 | C28: Thomas | D28: McGee | E28: M | F28: 26906 | G28: 29010 | L28: Spouse of Employee
B29: 7 | C29: Hunter | D29: McGee | E29: M | F29: 37098 | G29: 29010 | L29: Child of Employee
B30: 8 | C30: Harold | D30: Caldwell | E30: M | F30: 29478 | G30: 29501 | H30: Collector | I30: 24.07 | J30: F | L30: Employee
B31: 9 | C31: Jamie | D31: Caldwell | E31: F | F31: 39574 | G31: 29501 | L31: Child of Employee
B32: 10 | C32: Caroline | D32: Caldwell | E32: F | F32: 40553 | G32: 29501 | L32: Child of Employee
B33: 11 | C33: Addison | D33: Caldwell | E33: F | F33: 41184 | G33: 29501 | H33: Sr. Loan Officer | I33: 27.24 | J33: F | L33: Child of Employee
B34: 12 | C34: William | D34: Dalrymple | E34: M | F34: 22620 | G34: 29505 | L34: Employee
B35: 13 | C35: Coreen | D35: Dalrymple | E35: F | F35: 27226 | G35: 29505 | L35: Spouse of Employee
B36: 14 | C36: Robert | D36: Dalrymple | E36: M | F36: 40059 | G36: 29505 | L36: Child of Employee
B37: 15 | C37: Mark | D37: Bierwirth | E37: M | F37: 27212 | G37: 29501 | H37: Loan Officer | I37: 26 | J37: F | L37: Employee
B38: 16 | C38: Lenora | D38: Martin | E38: F | F38: 32612 | G38: 29532 | H38: Teller | I38: 17.43 | J38: F | L38: Employee
B39: 17 | C39: Kathryn E | D39: Tolson | E39: F | F39: 2//11/1980 | G39: 29532 | H39: Member Services Rep | I39: 20 | J39: F | L39: Employee
C40: Michale | D40: Tolson | E40: Male | F40: 29973 | G40: 29532 | L40: Spouse of Employee
B41: 18 | C41: Kathryn | D41: Tolson | E41: F | F41: 44418 | G41: 29532 | J41: F | L41: Child of Employee
B42: 19 | C42: Madison | D42: Millen | E42: F | F42: 32965 | G42: 29010 | H42: Teller | I42: 19.51 | L42: Employee
B43: 20 | C43: Jessie | D43: Gainey | E43: M | F43: 39963 | G43: 29010 | L43: Child of Employee
B44: 21 | C44: Graycen | D44: Millen | E44: F | F44: 42642 | G44: 29010 | L44: Child of Employee
B45: 22 | C45: Crystal | D45: Holsomback | E45: F | F45: 27409 | G45: 35643 | H45: Teller | I45: 18 | J45: F | L45: Employee
B46: 23 | C46: James | D46: Holsomback | E46: M | F46: 24378 | G46: 35643 | L46: Spouse of Employee
B47: 24 | C47: Elianna | D47: Holsomback | E47: F | F47: 41177 | G47: 35643 | L47: Child of Employee
B48: 25 | C48: James | D48: Holsomback | E48: M | F48: 40598 | G48: 35643 | L48: Child of Employee
B49: 26 | C49: Kirsten | D49: Calcutt | E49: F | F49: 37126 | G49: 29080 | H49: Teller | I49: 16 | J49: F | L49: Employee
B50: 27 | C50: Koa | D50: Priest | E50: M | F50: 44413 | G50: 29080 | L50: Child of Employee
B51: 28 | C51: Travis | D51: Sinclair | E51: M | F51: 31189 | G51: 29505 | H51: Accountant | I51: 63000 | J51: F | L51: Employee
B52: 29 | C52: Julie | D52: Sinclair | E52: F | F52: 31256 | G52: 29505 | L52: Spouse of Employee
B53: 30 | C53: Lincolon | D53: Sinclair | E53: M | F53: 44375 | G53: 29505 | L53: Child of Employee
B54: 31
...

Sheet Internal Use Only
B3: Company Name | D3: =Census!E15 -> Nucor Employee's Credit Union
B4: Headquarters Adress | D4: =Census!E16 -> 1202 N Cashua Dr. Florence, SC 29501
B5: Founding Year | D5: =Census!E17 -> 1962
B6: SIC Code | D6: =Census!#REF! -> #REF!
B7: Medical Effective Date | D7: =TEXT(Census!E19,"mm/dd/yyyy") -> 12/01/2027
B9: Currently Offers Health Insurance | D9: =Census!E18 -> Yes
B10: Current Providers | D10: =IF(#REF!<>"",#REF!,"N/A") -> #REF!
B11: Renewal Date | D11: =TEXT(#REF!,"mm/dd/yyyy") -> #REF!
B12: Currently on a PEO | D12: =Census!#REF! -> #REF!
B13: Current PEO | D13: =IF(#REF!<>"",#REF!,"N/A") -> #REF!
B15: Position on Census | C15: First Name | D15: Last Name | E15: Gender | F15: Date of Birth | G15: Home Zip Code | H15: Employee Code | I15: Cobra | J15: Home State | K15: Current Plan | L15: Current Monthly Premium | M15: Renewals Monthly Premium | N15: Current Enrollment Tier
B16: =Census!#REF! -> #REF! | C16: =IF(Census!#REF!<>"",Census!#REF!,"") -> #REF! | D16: =IF(Census!#REF!<>"",Census!#REF!,"") -> #REF! | E16: =IF(Census!#REF!<>"",Census!#REF!,"") -> #REF! | F16: =TEXT(IF(Census!#REF!,Census!#REF!,""),"mm/dd/yyyy") -> #REF! | G16: =IF(Census!#REF!<>"",TEXT(Census!#REF!,"00000"),"") -> #REF! | H16: {=IF(Census!#REF!<>"",INDEX(Definitions!$F$3:$F$12,MATCH(Census!#REF!,Definitions!$E$3:$E$12,0)),"")} -> #REF! | I16: =IF(Census!#REF!<>"",IF(Census!#REF!<>"COBRA Enrolee","No","Yes"),"") -> #REF! | J16: {=IF(G16<>"",INDEX(Definitions!$C$3:$C$74025,MATCH(G16,Definitions!$B$3:$B$74025,0)),"")} -> #REF! | K16: =IF(#REF!<>"",#REF!,"") -> #REF! | L16: =IF(#REF!>1,#REF!,"") -> #REF! | M16: =IF(#REF!>1,#REF!,"") -> #REF! | N16: {=IF(#REF!<>"",INDEX(Definitions!$F$14:$F$21,MATCH(#REF!,Definitions!$E$14:$E$21,0)),"")} -> #REF!
B17: =Census!#REF! -> #REF! | C17: =IF(Census!#REF!<>"",Census!#REF!,"") -> #REF! | D17: =IF(Census!#REF!<>"",Census!#REF!,"") -> #REF! | E17: =IF(Census!#REF!<>"",Census!#REF!,"") -> #REF! | F17: =TEXT(IF(Census!#REF!,Census!#REF!,""),"mm/dd/yyyy") -> #REF! | G17: =IF(Census!#REF!<>"",TEXT(Census!#REF!,"00000"),"") -> #REF! | H17: {=IF(Census!#REF!<>"",INDEX(Definitions!$F$3:$F$12,MATCH(Census!#REF!,Definitions!$E$3:$E$12,0)),"")} -> #REF! | I17: =IF(Census!#REF!<>"",IF(Census!#REF!<>"COBRA Enrolee","No","Yes"),"") -> #REF! | J17: {=IF(G17<>"",INDEX(Definitions!$C$3:$C$74025,MATCH(G17,Definitions!$B$3:$B$74025,0)),"")} -> #REF! | K17: =IF(#REF!<>"",#REF!,"") -> #REF! | L17: =IF(#REF!>1,#REF!,"") -> #REF! | M17: =IF(#REF!>1,#REF!,"") -> #REF! | N17: {=IF(#REF!<>"",INDEX(Definitions!$F$14:$F$21,MATCH(#REF!,Definitions!$E$14:$E$21,0)),"")} -> #REF!
B18: =Census!#REF! -> #REF! | C18: =IF(Census!#REF!<>"",Census!#REF!,"") -> #REF! | D18: =IF(Census!#REF!<>"",Census!#REF!,"") -> #REF! | E18: =IF(Census!#REF!<>"",Census!#REF!,"") -> #REF! | F18: =TEXT(IF(Census!#REF!,Census!#REF!,""),"mm/dd/yyyy") -> #REF! | G18: =IF(Census!#REF!<>"",TEXT(Census!#REF!,"00000"),"") -> #REF! | H18: {=IF(Census!#REF!<>"",INDEX(Definitions!$F$3:$F$12,MATCH(Census!#REF!,Definitions!$E$3:$E$12,0)),"")} -> #REF! | I18: =IF(Census!#REF!<>"",IF(Census!#REF!<>"COBRA Enrolee","No","Yes"),"") -> #REF! | J18: {=IF(G18<>"",INDEX(Definitions!$C$3:$C$74025,MATCH(G18,Definitions!$B$3:$B$74025,0)),"")} -> #REF! | K18: =IF(#REF!<>"",#REF!,"") -> #REF! | L18: =IF(#REF!>1,#REF!,"") -> #REF! | M18: =IF(#REF!>1,#REF!,"") -> #REF! | N18: {=IF(#REF!<>"",INDEX(Definitions!$F$14:$F$21,MATCH(#REF!,Definitions!$E$14:$E$21,0)),"")} -> #REF!
B19: =Census!#REF! -> #REF! | C19: =IF(Census!#REF!<>"",Census!#REF!,"") -> #REF! | D19: =IF(Census!#REF!<>"",Census!#REF!,"") -> #REF! | E19: =IF(Census!#REF!<>"",Census!#REF!,"") -> #REF! | F19: =TEXT(IF(Census!#REF!,Census!#REF!,""),"mm/dd/yyyy") -> #REF! | G19: =IF(Census!#REF!<>"",TEXT(Census!#REF!,"00000"),"") -> #REF! | H19: {=IF(Census!#REF!<>"",INDEX(Definitions!$F$3:$F$12,MATCH(Census!#REF!,Definitions!$E$3:$E$12,0)),"")} -> #REF! | I19: =IF(Census!#REF!<>"",IF(Census!#REF!<>"COBRA Enrolee","No","Yes"),"") -> #REF! | J19: {=IF(G19<>"",INDEX(Definitions!$C$3:$C$74025,MATCH(G19,Definitions!$B$3:$B$74025,0)),"")} -> #REF! | K19: =IF(#REF!<>"",#REF!,"") -> #REF! | L19: =IF(#REF!>1,#REF!,"") -> #REF! | M19: =IF(#REF!>1,#REF!,"") -> #REF! | N19: {=IF(#REF!<>"",INDEX(Definitions!$F$14:$F$21,MATCH(#REF!,Definitions!$E$14:$E$21,0)),"")} -> #REF!
B20: =Census!#REF! -> #REF! | C20: =IF(Census!#REF!<>"",Census!#REF!,"") -> #REF! | D20: =IF(Census!#REF!<>"",Census!#REF!,"") -> #REF! | E20: =IF(Census!#REF!<>"",Census!#REF!,"") -> #REF! | F20: =TEXT(IF(Census!#REF!,Census!#REF!,""),"mm/dd/yyyy") -> #REF! | G20: =IF(Census!#REF!<>"",TEXT(Census!#REF!,"00000"),"") -> #REF! | H20: {=IF(Census!#REF!<>"",INDEX(Definitions!$F$3:$F$12,MATCH(Census!#REF!,Definitions!$E$3:$E$12,0)),"")} -> #REF! | I20: =IF(Census!#REF!<>"",IF(Census!#REF!<>"COBRA Enrolee","No","Yes"),"") -> #REF! | J20: {=IF(G20<>"",INDEX(Definitions!$C$3:$C$74025,MATCH(G20,Definitions!$B$3:$B$74025,0)),"")} -> #REF! | K20: =IF(#REF!<>"",#REF!,"") -> #REF! | L20: =IF(#REF!>1,#REF!,"") -> #REF! | M20: =IF(#REF!>1,#REF!,"") -> #REF! | N20: {=IF(#REF!<>"",INDEX(Definitions!$F$14:$F$21,MATCH(#REF!,Definitions!$E$14:$E$21,0)),"")} -> #REF!
B21: =Census!#REF! -> #REF! | C21: =IF(Census!#REF!<>"",Census!#REF!,"") -> #REF! | D21: =IF(Census!#REF!<>"",Census!#REF!,"") -> #REF! | E21: =IF(Census!#REF!<>"",Census!#REF!,"") -> #REF! | F21: =TEXT(IF(Census!#REF!,Census!#REF!,""),"mm/dd/yyyy") -> #REF! | G21: =IF(Census!#REF!<>"",TEXT(Census!#REF!,"00000"),"") -> #REF! | H21: {=IF(Census!#REF!<>"",INDEX(Definitions!$F$3:$F$12,MATCH(Census!#REF!,Definitions!$E$3:$E$12,0)),"")} -> #REF! | I21: =IF(Census!#REF!<>"",IF(Census!#REF!<>"COBRA Enrolee","No","Yes"),"") -> #REF! | J21: {=IF(G21<>"",INDEX(Definitions!$C$3:$C$74025,MATCH(G21,Definitions!$B$3:$B$74025,0)),"")} -> #REF! | K21: =IF(#REF!<>"",#REF!,"") -> #REF! | L21: =IF(#REF!>1,#REF!,"") -> #REF! | M21: =IF(#REF!>1,#REF!,"") -> #REF! | N21: {=IF(#REF!<>"",INDEX(Definitions!$F$14:$F$21,MATCH(#REF!,Definitions!$E$14:$E$21,0)),"")} -> #REF!
B22: =Census!#REF! -> #REF! | C22: =IF(Census!#REF!<>"",Census!#REF!,"") -> #REF! | D22: =IF(Census!#REF!<>"",Census!#REF!,"") -> #REF! | E22: =IF(Census!#REF!<>"",Census!#REF!,"") -> #REF! | F22: =TEXT(IF(Census!#REF!,Census!#REF!,""),"mm/dd/yyyy") -> #REF! | G22: =IF(Census!#REF!<>"",TEXT(Census!#REF!,"00000"),"") -> #REF! | H22: {=IF(Census!#REF!<>"",INDEX(Definitions!$F$3:$F$12,MATCH(Census!#REF!,Definitions!$E$3:$E$12,0)),"")} -> #REF! | I22: =IF(Census!#REF!<>"",IF(Census!#REF!<>"COBRA Enrolee","No","Yes"),"") -> #REF! | J22: {=IF(G22<>"",INDEX(Definitions!$C$3:$C$74025,MATCH(G22,Definitions!$B$3:$B$74025,0)),"")} -> #REF! | K22: =IF(#REF!<>"",#REF!,"") -> #REF! | L22: =IF(#REF!>1,#REF!,"") -> #REF! | M22: =IF(#REF!>1,#REF!,"") -> #REF! | N22: {=IF(#REF!<>"",INDEX(Definitions!$F$14:$F$21,MATCH(#REF!,Definitions!$E$14:$E$21,0)),"")} -> #REF!
B23: =Census!#REF! -> #REF! | C23: =IF(Census!#REF!<>"",Census!#REF!,"") -> #REF! | D23: =IF(Census!#REF!<>"",Census!#REF!,"") -> #REF! | E23: =IF(Census!#REF!<>"",Census!#REF!,"") -> #REF! | F23: =TEXT(IF(Census!#REF!,Census!#REF!,""),"mm/dd/yyyy") -> #REF! | G23: =IF(Census!#REF!<>"",TEXT(Census!#REF!,"00000"),"") -> #REF! | H23: {=IF(Census!#REF!<>"",INDEX(Definitions!$F$3:$F$12,MATCH(Census!#REF!,Definitions!$E$3:$E$12,0)),"")} -> #REF! | I23: =IF(Census!#REF!<>"",IF(Census!#REF!<>"COBRA Enrolee","No","Yes"),"") -> #REF! | J23: {=IF(G23<>"",INDEX(Definitions!$C$3:$C$74025,MATCH(G23,Definitions!$B$3:$B$74025,0)),"")} -> #REF! | K23: =IF(#REF!<>"",#REF!,"") -> #REF! | L23: =IF(#REF!>1,#REF!,"") -> #REF! | M23: =IF(#REF!>1,#REF!,"") -> #REF! | N23: {=IF(#REF!<>"",INDEX(Definitions!$F$14:$F$21,MATCH(#REF!,Definitions!$E$14:$E$21,0)),"")} -> #REF!
B24: =Census!#REF! -> #REF! | C24: =IF(Census!#REF!<>"",Census!#REF!,"") -> #REF! | D24: =IF(Census!#REF!<>"",Census!#REF!,"") -> #REF! | E24: =IF(Census!#REF!<>"",Census!#REF!,"") -> #REF! | F24: =TEXT(IF(Census!#REF!,Census!#REF!,""),"mm/dd/yyyy") -> #REF! | G24: =IF(Census!#REF!<>"",TEXT(Census!#REF!,"00000"),"") -> #REF! | H24: {=IF(Census!#REF!<>"",INDEX(Definitions!$F$3:$F$12,MATCH(Census!#REF!,Definitions!$E$3:$E$12,0)),"")} -> #REF! | I24: =IF(Census!#REF!<>"",IF(Census!#REF!<>"COBRA Enrolee","No","Yes"),"") -> #REF! | J24: {=IF(G24<>"",INDEX(Definitions!$C$3:$C$74025,MATCH(G24,Definitions!$B$3:$B$74025,0)),"")} -> #REF! | K24: =IF(#REF!<>"",#REF!,"") -> #REF! | L24: =IF(#REF!>1,#REF!,"") -> #REF! | M24: =IF(#REF!>1,#REF!,"") -> #REF! | N24: {=IF(#REF!<>"",INDEX(Definitions!$F$14:$F$21,MATCH(#REF!,Definitions!$E$14:$E$21,0)),"")} -> #REF!
B25: =Census!#REF! -> #REF! | C25: =IF(Census!#REF!<>"",Census!#REF!,"") -> #REF! | D25: =IF(Census!#REF!<>"",Census!#REF!,"") -> #REF! | E25: =IF(Census!#REF!<>"",Census!#REF!,"") -> #REF! | F25: =TEXT(IF(Census!#REF!,Census!#REF!,""),"mm/dd/yyyy") -> #REF! | G25: =IF(Census!#REF!<>"",TEXT(Census!#REF!,"00000"),"") -> #REF! | H25: {=IF(Census!#REF!<>"",INDEX(Definitions!$F$3:$F$12,MATCH(Census!#REF!,Definitions!$E$3:$E$12,0)),"")} -> #REF! | I25: =IF(Census!#REF!<>"",IF(Census!#REF!<>"COBRA Enrolee","No","Yes"),"") -> #REF! | J25: {=IF(G25<>"",INDEX(Definitions!$C$3:$C$74025,MATCH(G25,Definitions!$B$3:$B$74025,0)),"")} -> #REF! | K25: =IF(#REF!<>"",#REF!,"") -> #REF! | L25: =IF(#REF!>1,#REF!,"") -> #REF! | M25: =IF(#REF!>1,#REF!,"") -> #REF! | N25: {=IF(#REF!<>"",INDEX(Definitions!$F$14:$F$21,MATCH(#REF!,Definitions!$E$14:$E$21,0)),"")} -> #REF!
B26: =Census!#REF! -> #REF! | C26: =IF(Census!#REF!<>"",Census!#REF!,"") -> #REF! | D26: =IF(Census!#REF!<>"",Census!#REF!,"") -> #REF! | E26: =IF(Census!#REF!<>"",Census!#REF!,"") -> #REF! | F26: =TEXT(IF(Census!#REF!,Census!#REF!,""),"mm/dd/yyyy") -> #REF! | G26: =IF(Census!#REF!<>"",TEXT(Census!#REF!,"00000"),"") -> #REF! | H26: {=IF(Census!#REF!<>"",INDEX(Definitions!$F$3:$F$12,MATCH(Census!#REF!,Definitions!$E$3:$E$12,0)),"")} -> #REF! | I26: =IF(Census!#REF!<>"",IF(Census!#REF!<>"COBRA Enrolee","No","Yes"),"") -> #REF! | J26: {=IF(G26<>"",INDEX(Definitions!$C$3:$C$74025,MATCH(G26,Definitions!$B$3:$B$74025,0)),"")} -> #REF! | K26: =IF(#REF!<>"",#REF!,"") -> #REF! | L26: =IF(#REF!>1,#REF!,"") -> #REF! | M26: =IF(#REF!>1,#REF!,"") -> #REF! | N26: {=IF(#REF!<>"",INDEX(Definitions!$F$14:$F$21,MATCH(#REF!,Definitions!$E$14:$E$21,0)),"")} -> #REF!
B27: =Census!#REF! -> #REF! | C27: =IF(Census!#REF!<>"",Census!#REF!,"") -> #REF! | D27: =IF(Census!#REF!<>"",Census!#REF!,"") -> #REF! | E27: =IF(Census!#REF!<>"",Census!#REF!,"") -> #REF! | F27: =TEXT(IF(Census!#REF!,Census!#REF!,""),"mm/dd/yyyy") -> #REF! | G27: =IF(Census!#REF!<>"",TEXT(Census!#REF!,"00000"),"") -> #REF! | H27: {=IF(Census!#REF!<>"",INDEX(Definitions!$F$3:$F$12,MATCH(Census!#REF!,Definitions!$E$3:$E$12,0)),"")} -> #REF! | I27: =IF(Census!#REF!<>"",IF(Census!#REF!<>"COBRA Enrolee","No","Yes"),"") -> #REF! | J27: {=IF(G27<>"",INDEX(Definitions!$C$3:$C$74025,MATCH(G27,Definitions!$B$3:$B$74025,0)),"")} -> #REF! | K27: =IF(#REF!<>"",#REF!,"") -> #REF! | L27: =IF(#REF!>1,#REF!,"") -> #REF! | M27: =IF(#REF!>1,#REF!,"") -> #REF! | N27: {=IF(#REF!<>"",INDEX(Definitions!$F$14:$F$21,MATCH(#REF!,Definitions!$E$14:$E$21,0)),"")} -> #REF!
... B29: =Census!#REF! -> #REF! | C29: =IF(Census!#REF!<>"",Census!#REF!,"") -> #REF! | D29: =IF(Census!#REF!<>"",Census!#REF!,"") -> #REF! | E29: =IF(Census!#REF!<>"",Census!#REF!,"") -> #REF! | F29: =TEXT(IF(Census!#REF!,Census!#REF!,""),"mm/dd/yyyy") -> #REF! | G29: =IF(Census!#REF!<>"",TEXT(Census!#REF!,"00000"),"") -> #REF! | H29: {=IF(Census!#REF!<>"",INDEX(Definitions!$F$3:$F$12,MATCH(Census!#REF!,Definitions!$E$3:$E$12,0)),"")} -> #REF! | I29: =IF(Census!#REF!<>"",IF(Census!#REF!<>"COBRA Enrolee","No","Yes"),"") -> #REF! | J29: {=IF(G29<>"",INDEX(Definitions!$C$3:$C$74025,MATCH(G29,Definitions!$B$3:$B$74025,0)),"")} -> #REF! | K29: =IF(#REF!<>"",#REF!,"") -> #REF! | L29: =IF(#REF!>1,#REF!,"") -> #REF! | M29: =IF(#REF!>1,#REF!,"") -> #REF! | N29: {=IF(#REF!<>"",INDEX(Definitions!$F$14:$F$21,MATCH(#REF!,Definitions!$E$14:$E$21,0)),"")} -> #REF!
B30: =Census!B23 -> 1 | C30: =IF(Census!C23<>"",Census!C23,"") -> Matthew | D30: =IF(Census!D23<>"",Census!D23,"") -> Chappell | E30: =IF(Census!E23<>"",Census!E23,"") -> M | F30: =TEXT(IF(Census!F23,Census!F23,""),"mm/dd/yyyy") -> 11/29/1987 | G30: =IF(Census!G23<>"",TEXT(Census!G23,"00000"),"") -> 29505 | H30: {=IF(Census!L23<>"",INDEX(Definitions!$F$3:$F$12,MATCH(Census!L23,Definitions!$E$3:$E$12,0)),"")} -> EE | I30: =IF(Census!L23<>"",IF(Census!L23<>"COBRA Enrolee","No","Yes"),"") -> No | J30: {=IF(G30<>"",INDEX(Definitions!$C$3:$C$74025,MATCH(G30,Definitions!$B$3:$B$74025,0)),"")} -> SC | K30: =IF(#REF!<>"",#REF!,"") -> #REF! | L30: =IF(#REF!>1,#REF!,"") -> #REF! | M30: =IF(#REF!>1,#REF!,"") -> #REF! | N30: {=IF(#REF!<>"",INDEX(Definitions!$F$14:$F$21,MATCH(#REF!,Definitions!$E$14:$E$21,0)),"")} -> #REF!
B31: =Census!B24 -> 2 | C31: =IF(Census!C24<>"",Census!C24,"") -> Amy | D31: =IF(Census!D24<>"",Census!D24,"") -> Chappell | E31: =IF(Census!E24<>"",Census!E24,"") -> F | F31: =TEXT(IF(Census!F24,Census!F24,""),"mm/dd/yyyy") -> 02/26/1988 | G31: =IF(Census!G24<>"",TEXT(Census!G24,"00000"),"") -> 29505 | H31: {=IF(Census!L24<>"",INDEX(Definitions!$F$3:$F$12,MATCH(Census!L24,Definitions!$E$3:$E$12,0)),"")} -> S | I31: =IF(Census!L24<>"",IF(Census!L24<>"COBRA Enrolee","No","Yes"),"") -> No | J31: {=IF(G31<>"",INDEX(Definitions!$C$3:$C$74025,MATCH(G31,Definitions!$B$3:$B$74025,0)),"")} -> SC | K31: =IF(#REF!<>"",#REF!,"") -> #REF! | L31: =IF(#REF!>1,#REF!,"") -> #REF! | M31: =IF(#REF!>1,#REF!,"") -> #REF! | N31: {=IF(#REF!<>"",INDEX(Definitions!$F$14:$F$21,MATCH(#REF!,Definitions!$E$14:$E$21,0)),"")} -> #REF!
B32: =Census!B25 -> 3 | C32: =IF(Census!C25<>"",Census!C25,"") -> Silas | D32: =IF(Census!D25<>"",Census!D25,"") -> Chappell | E32: =IF(Census!E25<>"",Census!E25,"") -> M | F32: =TEXT(IF(Census!F25,Census!F25,""),"mm/dd/yyyy") -> 06/17/2022 | G32: =IF(Census!G25<>"",TEXT(Census!G25,"00000"),"") -> 29505 | H32: {=IF(Census!L25<>"",INDEX(Definitions!$F$3:$F$12,MATCH(Census!L25,Definitions!$E$3:$E$12,0)),"")} -> C | I32: =IF(Census!L25<>"",IF(Census!L25<>"COBRA Enrolee","No","Yes"),"") -> No | J32: {=IF(G32<>"",INDEX(Definitions!$C$3:$C$74025,MATCH(G32,Definitions!$B$3:$B$74025,0)),"")} -> SC | K32: =IF(#REF!<>"",#REF!,"") -> #REF! | L32: =IF(#REF!>1,#REF!,"") -> #REF! | M32: =IF(#REF!>1,#REF!,"") -> #REF! | N32: {=IF(#REF!<>"",INDEX(Definitions!$F$14:$F$21,MATCH(#REF!,Definitions!$E$14:$E$21,0)),"")} -> #REF!
B33: =Census!B26 -> 4 | C33: =IF(Census!C26<>"",Census!C26,"") -> Isaac | D33: =IF(Census!D26<>"",Census!D26,"") -> Chappell | E33: =IF(Census!E26<>"",Census!E26,"") -> M | F33: =TEXT(IF(Census!F26,Census!F26,""),"mm/dd/yyyy") -> 05/03/2024 | G33: =IF(Census!G26<>"",TEXT(Census!G26,"00000"),"") -> 29505 | H33: {=IF(Census!L26<>"",INDEX(Definitions!$F$3:$F$12,MATCH(Census!L26,Definitions!$E$3:$E$12,0)),"")} -> C | I33: =IF(Census!L26<>"",IF(Census!L26<>"COBRA Enrolee","No","Yes"),"") -> No | J33: {=IF(G33<>"",INDEX(Definitions!$C$3:$C$74025,MATCH(G33,Definitions!$B$3:$B$74025,0)),"")} -> SC | K33: =IF(#REF!<>"",#REF!,"") -> #REF! | L33: =IF(#REF!>1,#REF!,"") -> #REF! | M33: =IF(#REF!>1,#REF!,"") -> #REF! | N33: {=IF(#REF!<>"",INDEX(Definitions!$F$14:$F$21,MATCH(#REF!,Definitions!$E$14:$E$21,0)),"")} -> #REF!
B34: =Census!B27 -> 5 | C34: =IF(Census!C27<>"",Census!C27,"") -> Debbie | D34: =IF(Census!D27<>"",Census!D27,"") -> McGee | E34: =IF(Census!E27<>"",Census!E27,"") -> F | F34: =TEXT(IF(Census!F27,Census!F27,""),"mm/dd/yyyy") -> 12/22/1971 | G34: =IF(Census!G27<>"",TEXT(Census!G27,"00000"),"") -> 29010 | H34: {=IF(Census!L27<>"",INDEX(Definitions!$F$3:$F$12,MATCH(Census!L27,Definitions!$E$3:$E$12,0)),"")} -> EE | I34: =IF(Census!L27<>"",IF(Census!L27<>"COBRA Enrolee","No","Yes"),"") -> No | J34: {=IF(G34<>"",INDEX(Definitions!$C$3:$C$74025,MATCH(G34,Definitions!$B$3:$B$74025,0)),"")} -> SC | K34: =IF(#REF!<>"",#REF!,"") -> #REF! | L34: =IF(#REF!>1,#REF!,"") -> #REF! | M34: =IF(#REF!>1,#REF!,"") -> #REF! | N34: {=IF(#REF!<>"",INDEX(Definitions!$F$14:$F$21,MATCH(#REF!,Definitions!$E$14:$E$21,0)),"")} -> #REF!
B35: =Census!B28 -> 6 | C35: =IF(Census!C28<>"",Census!C28,"") -> Thomas | D35: =IF(Census!D28<>"",Census!D28,"") -> McGee | E35: =IF(Census!E28<>"",Census!E28,"") -> M | F35: =TEXT(IF(Census!F28,Census!F28,""),"mm/dd/yyyy") -> 08/30/1973 | G35: =IF(Census!G28<>"",TEXT(Census!G28,"00000"),"") -> 29010 | H35: {=IF(Census!L28<>"",INDEX(Definitions!$F$3:$F$12,MATCH(Census!L28,Definitions!$E$3:$E$12,0)),"")} -> S | I35: =IF(Census!L28<>"",IF(Census!L28<>"COBRA Enrolee","No","Yes"),"") -> No | J35: {=IF(G35<>"",INDEX(Definitions!$C$3:$C$74025,MATCH(G35,Definitions!$B$3:$B$74025,0)),"")} -> SC | K35: =IF(#REF!<>"",#REF!,"") -> #REF! | L35: =IF(#REF!>1,#REF!,"") -> #REF! | M35: =IF(#REF!>1,#REF!,"") -> #REF! | N35: {=IF(#REF!<>"",INDEX(Definitions!$F$14:$F$21,MATCH(#REF!,Definitions!$E$14:$E$21,0)),"")} -> #REF!
B36: =Census!B29 -> 7 | C36: =IF(Census!C29<>"",Census!C29,"") -> Hunter | D36: =IF(Census!D29<>"",Census!D29,"") -> McGee | E36: =IF(Census!E29<>"",Census!E29,"") -> M | F36: =TEXT(IF(Census!F29,Census!F29,""),"mm/dd/yyyy") -> 07/26/2001 | G36: =IF(Census!G29<>"",TEXT(Census!G29,"00000"),"") -> 29010 | H36: {=IF(Census!L29<>"",INDEX(Definitions!$F$3:$F$12,MATCH(Census!L29,Definitions!$E$3:$E$12,0)),"")} -> C | I36: =IF(Census!L29<>"",IF(Census!L29<>"COBRA Enrolee","No","Yes"),"") -> No | J36: {=IF(G36<>"",INDEX(Definitions!$C$3:$C$74025,MATCH(G36,Definitions!$B$3:$B$74025,0)),"")} -> SC | K36: =IF(#REF!<>"",#REF!,"") -> #REF! | L36: =IF(#REF!>1,#REF!,"") -> #REF! | M36: =IF(#REF!>1,#REF!,"") -> #REF! | N36: {=IF(#REF!<>"",INDEX(Definitions!$F$14:$F$21,MATCH(#REF!,Definitions!$E$14:$E$21,0)),"")} -> #REF!
B37: =Census!B30 -> 8 | C37: =IF(Census!C30<>"",Census!C30,"") -> Harold | D37: =IF(Census!D30<>"",Census!D30,"") -> Caldwell | E37: =IF(Census!E30<>"",Census!E30,"") -> M | F37: =TEXT(IF(Census!F30,Census!F30,""),"mm/dd/yyyy") -> 09/14/1980 | G37: =IF(Census!G30<>"",TEXT(Census!G30,"00000"),"") -> 29501 | H37: {=IF(Census!L30<>"",INDEX(Definitions!$F$3:$F$12,MATCH(Census!L30,Definitions!$E$3:$E$12,0)),"")} -> EE | I37: =IF(Census!L30<>"",IF(Census!L30<>"COBRA Enrolee","No","Yes"),"") -> No | J37: {=IF(G37<>"",INDEX(Definitions!$C$3:$C$74025,MATCH(G37,Definitions!$B$3:$B$74025,0)),"")} -> SC | K37: =IF(#REF!<>"",#REF!,"") -> #REF! | L37: =IF(#REF!>1,#REF!,"") -> #REF! | M37: =IF(#REF!>1,#REF!,"") -> #REF! | N37: {=IF(#REF!<>"",INDEX(Definitions!$F$14:$F$21,MATCH(#REF!,Definitions!$E$14:$E$21,0)),"")} -> #REF!
B38: =Census!B31 -> 9 | C38: =IF(Census!C31<>"",Census!C31,"") -> Jamie | D38: =IF(Census!D31<>"",Census!D31,"") -> Caldwell | E38: =IF(Census!E31<>"",Census!E31,"") -> F | F38: =TEXT(IF(Census!F31,Census!F31,""),"mm/dd/yyyy") -> 05/06/2008 | G38: =IF(Census!G31<>"",TEXT(Census!G31,"00000"),"") -> 29501 | H38: {=IF(Census!L31<>"",INDEX(Definitions!$F$3:$F$12,MATCH(Census!L31,Definitions!$E$3:$E$12,0)),"")} -> C | I38: =IF(Census!L31<>"",IF(Census!L31<>"COBRA Enrolee","No","Yes"),"") -> No | J38: {=IF(G38<>"",INDEX(Definitions!$C$3:$C$74025,MATCH(G38,Definitions!$B$3:$B$74025,0)),"")} -> SC | K38: =IF(#REF!<>"",#REF!,"") -> #REF! | L38: =IF(#REF!>1,#REF!,"") -> #REF! | M38: =IF(#REF!>1,#REF!,"") -> #REF! | N38: {=IF(#REF!<>"",INDEX(Definitions!$F$14:$F$21,MATCH(#REF!,Definitions!$E$14:$E$21,0)),"")} -> #REF!
B39: =Census!B32 -> 10 | C39: =IF(Census!C32<>"",Census!C32,"") -> Caroline | D39: =IF(Census!D32<>"",Census!D32,"") -> Caldwell | E39: =IF(Census!E32<>"",Census!E32,"") -> F | F39: =TEXT(IF(Census!F32,Census!F32,""),"mm/dd/yyyy") -> 01/10/2011 | G39: =IF(Census!G32<>"",TEXT(Census!G32,"00000"),"") -> 29501 | H39: {=IF(Census!L32<>"",INDEX(Definitions!$F$3:$F$12,MATCH(Census!L32,Definitions!$E$3:$E$12,0)),"")} -> C | I39: =IF(Census!L32<>"",IF(Census!L32<>"COBRA Enrolee","No","Yes"),"") -> No | J39: {=IF(G39<>"",INDEX(Definitions!$C$3:$C$74025,MATCH(G39,Definitions!$B$3:$B$74025,0)),"")} -> SC | K39: =IF(#REF!<>"",#REF!,"") -> #REF! | L39: =IF(#REF!>1,#REF!,"") -> #REF! | M39: =IF(#REF!>1,#REF!,"") -> #REF! | N39: {=IF(#REF!<>"",INDEX(Definitions!$F$14:$F$21,MATCH(#REF!,Definitions!$E$14:$E$21,0)),"")} -> #REF!
B40: =Census!B33 -> 11 | C40: =IF(Census!C33<>"",Census!C33,"") -> Addison | D40: =IF(Census!D33<>"",Census!D33,"") -> Caldwell | E40: =IF(Census!E33<>"",Census!E33,"") -> F | F40: =TEXT(IF(Census!F33,Census!F33,""),"mm/dd/yyyy") -> 10/02/2012 | G40: =IF(Census!G33<>"",TEXT(Census!G33,"00000"),"") -> 29501 | H40: {=IF(Census!L33<>"",INDEX(Definitions!$F$3:$F$12,MATCH(Census!L33,Definitions!$E$3:$E$12,0)),"")} -> C | I40: =IF(Census!L33<>"",IF(Census!L33<>"COBRA Enrolee","No","Yes"),"") -> No | J40: {=IF(G40<>"",INDEX(Definitions!$C$3:$C$74025,MATCH(G40,Definitions!$B$3:$B$74025,0)),"")} -> SC | K40: =IF(#REF!<>"",#REF!,"") -> #REF! | L40: =IF(#REF!>1,#REF!,"") -> #REF! | M40: =IF(#REF!>1,#REF!,"") -> #REF! | N40: {=IF(#REF!<>"",INDEX(Definitions!$F$14:$F$21,MATCH(#REF!,Definitions!$E$14:$E$21,0)),"")} -> #REF!
B41: =Census!B34 -> 12 | C41: =IF(Census!C34<>"",Census!C34,"") -> William | D41: =IF(Census!D34<>"",Census!D34,"") -> Dalrymple | E41: =IF(Census!E34<>"",Census!E34,"") -> M | F41: =TEXT(IF(Census!F34,Census!F34,""),"mm/dd/yyyy") -> 12/05/1961 | G41: =IF(Census!G34<>"",TEXT(Census!G34,"00000"),"") -> 29505 | H41: {=IF(Census!L34<>"",INDEX(Definitions!$F$3:$F$12,MATCH(Census!L34,Definitions!$E$3:$E$12,0)),"")} -> EE | I41: =IF(Census!L34<>"",IF(Census!L34<>"COBRA Enrolee","No","Yes"),"") -> No | J41: {=IF(G41<>"",INDEX(Definitions!$C$3:$C$74025,MATCH(G41,Definitions!$B$3:$B$74025,0)),"")} -> SC | K41: =IF(#REF!<>"",#REF!,"") -> #REF! | L41: =IF(#REF!>1,#REF!,"") -> #REF! | M41: =IF(#REF!>1,#REF!,"") -> #REF! | N41: {=IF(#REF!<>"",INDEX(Definitions!$F$14:$F$21,MATCH(#REF!,Definitions!$E$14:$E$21,0)),"")} -> #REF!
... B46: =Census!B39 -> 17 | C46: =IF(Census!C39<>"",Census!C39,"") -> Kathryn E | D46: =IF(Census!D39<>"",Census!D39,"") -> Tolson | E46: =IF(Census!E39<>"",Census!E39,"") -> F | F46: =TEXT(IF(Census!F39,Census!F39,""),"mm/dd/yyyy") -> #VALUE! | G46: =IF(Census!G39<>"",TEXT(Census!G39,"00000"),"") -> 29532 | H46: {=IF(Census!L39<>"",INDEX(Definitions!$F$3:$F$12,MATCH(Census!L39,Definitions!$E$3:$E$12,0)),"")} -> EE | I46: =IF(Census!L39<>"",IF(Census!L39<>"COBRA Enrolee","No","Yes"),"") -> No | J46: {=IF(G46<>"",INDEX(Definitions!$C$3:$C$74025,MATCH(G46,Definitions!$B$3:$B$74025,0)),"")} -> SC | K46: =IF(#REF!<>"",#REF!,"") -> #REF! | L46: =IF(#REF!>1,#REF!,"") -> #REF! | M46: =IF(#REF!>1,#REF!,"") -> #REF! | N46: {=IF(#REF!<>"",INDEX(Definitions!$F$14:$F$21,MATCH(#REF!,Definitions!$E$14:$E$21,0)),"")} -> #REF!
B47: =Census!B41 -> 18 | C47: =IF(Census!C41<>"",Census!C41,"") -> Kathryn | D47: =IF(Census!D41<>"",Census!D41,"") -> Tolson | E47: =IF(Census!E41<>"",Census!E41,"") -> F | F47: =TEXT(IF(Census!F41,Census!F41,""),"mm/dd/yyyy") -> 08/10/2021 | G47: =IF(Census!G41<>"",TEXT(Census!G41,"00000"),"") -> 29532 | H47: {=IF(Census!L41<>"",INDEX(Definitions!$F$3:$F$12,MATCH(Census!L41,Definitions!$E$3:$E$12,0)),"")} -> C | I47: =IF(Census!L41<>"",IF(Census!L41<>"COBRA Enrolee","No","Yes"),"") -> No | J47: {=IF(G47<>"",INDEX(Definitions!$C$3:$C$74025,MATCH(G47,Definitions!$B$3:$B$74025,0)),"")} -> SC | K47: =IF(#REF!<>"",#REF!,"") -> #REF! | L47: =IF(#REF!>1,#REF!,"") -> #REF! | M47: =IF(#REF!>1,#REF!,"") -> #REF! | N47: {=IF(#REF!<>"",INDEX(Definitions!$F$14:$F$21,MATCH(#REF!,Definitions!$E$14:$E$21,0)),"")} -> #REF!
B48: =Census!B42 -> 19 | C48: =IF(Census!C42<>"",Census!C42,"") -> Madison | D48: =IF(Census!D42<>"",Census!D42,"") -> Millen | E48: =IF(Census!E42<>"",Census!E42,"") -> F | F48: =TEXT(IF(Census!F42,Census!F42,""),"mm/dd/yyyy") -> 04/02/1990 | G48: =IF(Census!G42<>"",TEXT(Census!G42,"00000"),"") -> 29010 | H48: {=IF(Census!L42<>"",INDEX(Definitions!$F$3:$F$12,MATCH(Census!L42,Definitions!$E$3:$E$12,0)),"")} -> EE | I48: =IF(Census!L42<>"",IF(Census!L42<>"COBRA Enrolee","No","Yes"),"") -> No | J48: {=IF(G48<>"",INDEX(Definitions!$C$3:$C$74025,MATCH(G48,Definitions!$B$3:$B$74025,0)),"")} -> SC | K48: =IF(#REF!<>"",#REF!,"") -> #REF! | L48: =IF(#REF!>1,#REF!,"") -> #REF! | M48: =IF(#REF!>1,#REF!,"") -> #REF! | N48: {=IF(#REF!<>"",INDEX(Definitions!$F$14:$F$21,MATCH(#REF!,Definitions!$E$14:$E$21,0)),"")} -> #REF!
B49: =Census!B43 -> 20 | C49: =IF(Census!C43<>"",Census!C43,"") -> Jessie | D49: =IF(Census!D43<>"",Census!D43,"") -> Gainey | E49: =IF(Census!E43<>"",Census!E43,"") -> M | F49: =TEXT(IF(Census!F43,Census!F43,""),"mm/dd/yyyy") -> 05/30/2009 | G49: =IF(Census!G43<>"",TEXT(Census!G43,"00000"),"") -> 29010 | H49: {=IF(Census!L43<>"",INDEX(Definitions!$F$3:$F$12,MATCH(Census!L43,Definitions!$E$3:$E$12,0)),"")} -> C | I49: =IF(Census!L43<>"",IF(Census!L43<>"COBRA Enrolee","No","Yes"),"") -> No | J49: {=IF(G49<>"",INDEX(Definitions!$C$3:$C$74025,MATCH(G49,Definitions!$B$3:$B$74025,0)),"")} -> SC | K49: =IF(#REF!<>"",#REF!,"") -> #REF! | L49: =IF(#REF!>1,#REF!,"") -> #REF! | M49: =IF(#REF!>1,#REF!,"") -> #REF! | N49: {=IF(#REF!<>"",INDEX(Definitions!$F$14:$F$21,MATCH(#REF!,Definitions!$E$14:$E$21,0)),"")} -> #REF!
...

Sheet Definitions
B3: ZIP Code | C3: State | E3: Employee Type | F3: Code1 | H3: Gender Options | J3: Yes or No
B4: 99546 | C4: AK | E4: Owner | F4: EE | H4: Female | J4: Yes
B5: 99571 | C5: AK | E5: Employee | F5: EE | H5: Male | J5: No
B6: 99615 | C6: AK | E6: Spouse of Employee | F6: S
B7: 99551 | C7: AK | E7: Child of Employee | F7: C
B8: 99552 | C8: AK | E8: Plans to Waive Benefits | F8: =""
B9: 99553 | C9: AK | E9: Refusing Coverage
B10: 99554 | C10: AK | E10: Not Eligible for Benefits | F10: =""
B11: 99555 | C11: AK | E11: COBRA Enrollee | F11: =""
B12: 99720 | C12: AK | F12: =""
B13: 99786 | C13: AK
B14: 99721 | C14: AK | E14: Employee Type | F14: Code1
B15: 99721 | C15: AK | E15: Employee Only | F15: EE
B16: 99505 | C16: AK | E16: Employee and Spouse | F16: ES
B17: 99556 | C17: AK | E17: Employee and Child | F17: EC
B18: 99501 | C18: AK | E18: Employee and Family | F18: Fam
B19: 99502 | C19: AK | E19: Has Waived Benefits | F19: Waived
B20: 99503 | C20: AK | E20: Refusing Coverage
B21: 99504 | C21: AK | E21: Not Eligible for Benefits | F21: =""
B22: 99505 | C22: AK
B23: 99506 | C23: AK | F23: =""
B24: 99507 | C24: AK
B25: 99508 | C25: AK
B26: 99509 | C26: AK
B27: 99510 | C27: AK
B28: 99511 | C28: AK
B29: 99513 | C29: AK
B30: 99514 | C30: AK
B31: 99515 | C31: AK
B32: 99516 | C32: AK
B33: 99517 | C33: AK
B34: 99518 | C34: AK
B35: 99519 | C35: AK
... B74025: 82244 | C74025: WY
